---------------------------------------------------------------------------
gaierror                                  Traceback (most recent call last)
C:\Users\All Users\Anaconda3\lib\site-packages\urllib3\connection.py in _new_conn(self)
    159             conn = connection.create_connection(
--> 160                 (self._dns_host, self.port), self.timeout, **extra_kw
    161             )

C:\Users\All Users\Anaconda3\lib\site-packages\urllib3\util\connection.py in create_connection(address, timeout, source_address, socket_options)
     60 
---> 61     for res in socket.getaddrinfo(host, port, family, socket.SOCK_STREAM):
     62         af, socktype, proto, canonname, sa = res

C:\ProgramData\Anaconda3\lib\socket.py in getaddrinfo(host, port, family, type, proto, flags)
    751     addrlist = []
--> 752     for res in _socket.getaddrinfo(host, port, family, type, proto, flags):
    753         af, socktype, proto, canonname, sa = res

gaierror: [Errno 11004] getaddrinfo failed

During handling of the above exception, another exception occurred:

NewConnectionError                        Traceback (most recent call last)
C:\Users\All Users\Anaconda3\lib\site-packages\urllib3\connectionpool.py in urlopen(self, method, url, body, headers, retries, redirect, assert_same_host, timeout, pool_timeout, release_conn, chunked, body_pos, **response_kw)
    676                 headers=headers,
--> 677                 chunked=chunked,
    678             )

C:\Users\All Users\Anaconda3\lib\site-packages\urllib3\connectionpool.py in _make_request(self, conn, method, url, timeout, chunked, **httplib_request_kw)
    380         try:
--> 381             self._validate_conn(conn)
    382         except (SocketTimeout, BaseSSLError) as e:

C:\Users\All Users\Anaconda3\lib\site-packages\urllib3\connectionpool.py in _validate_conn(self, conn)
    975         if not getattr(conn, "sock", None):  # AppEngine might not have  `.sock`
--> 976             conn.connect()
    977 

C:\Users\All Users\Anaconda3\lib\site-packages\urllib3\connection.py in connect(self)
    307         # Add certificate verification
--> 308         conn = self._new_conn()
    309         hostname = self.host

C:\Users\All Users\Anaconda3\lib\site-packages\urllib3\connection.py in _new_conn(self)
    171             raise NewConnectionError(
--> 172                 self, "Failed to establish a new connection: %s" % e
    173             )

NewConnectionError: <urllib3.connection.HTTPSConnection object at 0x0AC59B50>: Failed to establish a new connection: [Errno 11004] getaddrinfo failed

During handling of the above exception, another exception occurred:

MaxRetryError                             Traceback (most recent call last)
C:\Users\All Users\Anaconda3\lib\site-packages\requests\adapters.py in send(self, request, stream, timeout, verify, cert, proxies)
    448                     retries=self.max_retries,
--> 449                     timeout=timeout
    450                 )

C:\Users\All Users\Anaconda3\lib\site-packages\urllib3\connectionpool.py in urlopen(self, method, url, body, headers, retries, redirect, assert_same_host, timeout, pool_timeout, release_conn, chunked, body_pos, **response_kw)
    724             retries = retries.increment(
--> 725                 method, url, error=e, _pool=self, _stacktrace=sys.exc_info()[2]
    726             )

C:\Users\All Users\Anaconda3\lib\site-packages\urllib3\util\retry.py in increment(self, method, url, response, error, _pool, _stacktrace)
    438         if new_retry.is_exhausted():
--> 439             raise MaxRetryError(_pool, url, error or ResponseError(cause))
    440 

MaxRetryError: HTTPSConnectionPool(host='api.upbit.com', port=443): Max retries exceeded with url: /v1/accounts (Caused by NewConnectionError('<urllib3.connection.HTTPSConnection object at 0x0AC59B50>: Failed to establish a new connection: [Errno 11004] getaddrinfo failed'))

During handling of the above exception, another exception occurred:

ConnectionError                           Traceback (most recent call last)
<ipython-input-2-6dbca31683f8> in <module>
    571     #     print("0보다 크다")
    572     Call_Price_Possible, Call_Volume_Possible = Call_Condition(File_Name)
--> 573     Start_BIT_Trade(Call_Price_Possible, Call_Volume_Possible, File_Name)

<ipython-input-2-6dbca31683f8> in Start_BIT_Trade(Call_Price_Possible, Call_Volume_Possible, File_Name)
    458         headers = {"Authorization": authorize_token}
    459 
--> 460         res = requests.get(server_url + "/v1/accounts", headers=headers)
    461 
    462         if len(res.json()) < 2 :

C:\Users\All Users\Anaconda3\lib\site-packages\requests\api.py in get(url, params, **kwargs)
     74 
     75     kwargs.setdefault('allow_redirects', True)
---> 76     return request('get', url, params=params, **kwargs)
     77 
     78 

C:\Users\All Users\Anaconda3\lib\site-packages\requests\api.py in request(method, url, **kwargs)
     59     # cases, and look like a memory leak in others.
     60     with sessions.Session() as session:
---> 61         return session.request(method=method, url=url, **kwargs)
     62 
     63 

C:\Users\All Users\Anaconda3\lib\site-packages\requests\sessions.py in request(self, method, url, params, data, headers, cookies, files, auth, timeout, allow_redirects, proxies, hooks, stream, verify, cert, json)
    528         }
    529         send_kwargs.update(settings)
--> 530         resp = self.send(prep, **send_kwargs)
    531 
    532         return resp

C:\Users\All Users\Anaconda3\lib\site-packages\requests\sessions.py in send(self, request, **kwargs)
    641 
    642         # Send the request
--> 643         r = adapter.send(request, **kwargs)
    644 
    645         # Total elapsed time of the request (approximately)

C:\Users\All Users\Anaconda3\lib\site-packages\requests\adapters.py in send(self, request, stream, timeout, verify, cert, proxies)
    514                 raise SSLError(e, request=request)
    515 
--> 516             raise ConnectionError(e, request=request)
    517 
    518         except ClosedPoolError as e:

ConnectionError: HTTPSConnectionPool(host='api.upbit.com', port=443):
 Max retries exceeded with url: /v1/accounts
 (Caused by NewConnectionError('<urllib3.connection.HTTPSConnection object at 0x0AC59B50>:
 Failed to establish a new connection: [Errno 11004] getaddrinfo failed'))

